<?xml version="1.0"?>
<robot name="quadruped_spider" xmlns:xacro="http://www.ros.org/wiki/xacro">

    <xacro:include filename="./quadruped_robot_inertial.urdf.xacro"/>
    <!--<xacro:include filename="$(find rospackage)/path"/>-->

    <link name="body_link">
        <visual>
            <origin xyz="0 0 0.00215" rpy="0 0 0"/>
            <geometry>
                <mesh filename="package://quadruped_robot_description/meshes/body_top-plate.stl"/>
            </geometry>
        </visual>
        <!--<collision>
            <origin xyz="0 0 0.00215" rpy="0 0 0" />
            <geometry>
                <box size="0.076 0.076 0.0045"/>
            </geometry>
        </collision>-->
        <collision>
            <origin xyz="0 0 0.00215" rpy="0 0 0" />
            <geometry>
                <mesh filename="package://quadruped_robot_description/meshes/body_top-plate_collision.stl"/>
            </geometry>
        </collision>
        <xacro:body_inertial/>
    </link>

    <!-- batteries -->
    <xacro:battery nr="1" reflect_lr="1"/>
    <xacro:battery nr="2" reflect_lr="-1"/>

    <!-- left and right foreleg -->
    <xacro:leg leg_nr="LF" reflect_fh="1" reflect_lr="1"/>
    <xacro:leg leg_nr="RF" reflect_fh="1" reflect_lr="-1"/>
    <!-- left and right hindleg -->
    <xacro:leg leg_nr="LH" reflect_fh="-1" reflect_lr="1"/>
    <xacro:leg leg_nr="RH" reflect_fh="-1" reflect_lr="-1"/>

    <xacro:macro name="leg" params="leg_nr leg_name_prefix:=Leg- reflect_fh reflect_lr">
        <xacro:property name="leg_name" value="${leg_name_prefix}${leg_nr}"/>

        <!--###### hip abduction/adduction joint ######-->
        <joint name="${leg_name}-HAA_joint" type="revolute">
            <parent link="body_link"/><!--<parent link="${parent}"/>-->
            <child link="${leg_name}-Hip_link"/>
            <origin xyz="${reflect_fh * 0.033} ${reflect_lr * 0.033} -0.02275"
                rpy="${-3*pi/4 + pi/4 * reflect_fh * reflect_lr} ${pi/2} ${(1 - reflect_lr) * pi/2}"/>
            <axis xyz="1 0 0"/>
            <dynamics damping="0.00001"/>
            <limit lower="0.0" upper="${pi/2}" velocity="1.0" effort="0.0"/>
            <!-- <calibration rising_and_or_falling=""/> -->
        </joint>

        <link name="${leg_name}-Hip_link"/>

        <joint name="${leg_name}-Hip-part1_joint" type="fixed">
            <parent link="${leg_name}-Hip_link"/>
            <child link="${leg_name}-Hip-part1_link"/>
            <origin xyz="${-0.02275 + 0.012 - 0.0043/2} 0 0" rpy="0 ${-pi/2} ${pi/2 + pi/2 * reflect_fh * reflect_lr}"/>
        </joint>

        <link name="${leg_name}-Hip-part1_link">
            <visual>
                <origin xyz="0 0 0" rpy="0 0 0"/>
                <geometry>
                    <mesh filename="package://quadruped_robot_description/meshes/hip_part1.stl"/>
                </geometry>
            </visual>
            <!--<collision>
                <origin xyz="0 0 0" rpy="0 0 0" />
                <geometry>
                    <box size="0.005 0.005 0.005"/>
                </geometry>
            </collision>-->
            <collision>
                <origin xyz="0 0 0" rpy="0 0 0" />
                <geometry>
                    <mesh filename="package://quadruped_robot_description/meshes/hip_part1_collision.stl"/>
                </geometry>
            </collision>
            <xacro:hip_part1_inertial/>
        </link>

        <joint name="${leg_name}-Hip-part2_joint" type="fixed">
            <parent link="${leg_name}-Hip_link"/>
            <child link="${leg_name}-Hip-part2_link"/>
            <origin xyz="0 0 0.02275" rpy="${-pi/2} ${pi/2} 0"/>
        </joint>

        <link name="${leg_name}-Hip-part2_link">
            <visual>
                <origin xyz="0 0 0" rpy="0 0 0"/>
                <geometry>
                    <mesh filename="package://quadruped_robot_description/meshes/hip_part2.stl"/>
                </geometry>
            </visual>
            <!--<collision>
                <origin xyz="0 0 0" rpy="0 0 0" />
                <geometry>
                    <box size="0.005 0.005 0.005"/>
                </geometry>
            </collision>-->
            <collision>
                <origin xyz="0 0 0" rpy="0 0 0" />
                <geometry>
                    <mesh filename="package://quadruped_robot_description/meshes/hip_part2_collision.stl"/>
                </geometry>
            </collision>
            <xacro:hip_part2_inertial/>
        </link>

        <gazebo reference="${leg_name}-Hip_link">
            <selfCollide>true</selfCollide>
        </gazebo>

        <xacro:servo name_suffix="${leg_name}-HAA" parent="${leg_name}-Hip_link"
            xyz="-0.02275 0 0" rpy="0 ${pi/2 + pi/2 * reflect_lr * reflect_fh} ${pi/2}"/>

        <xacro:servo name_suffix="${leg_name}-HFE" parent="${leg_name}-Hip_link"
            xyz="0 ${-(0.0077 + 0.0043/2) * reflect_lr * reflect_fh} 0.02275"
            rpy="${pi/2 + pi/2 * reflect_lr * reflect_fh} 0 0"/>

        <!--###### hip flexion/extension joint ######-->
        <joint name="${leg_name}-HFE_joint" type="revolute">
            <parent link="${leg_name}-Hip_link"/>
            <child link="${leg_name}-Thigh_link"/>
            <origin xyz="0 0 0.02275"
                rpy="${-pi/2} 0 ${-pi/2 * reflect_lr * reflect_fh}"/>
            <axis xyz="1 0 0"/>
            <dynamics damping="0.00001"/>
            <limit lower="0.0" upper="${pi}" velocity="1.0" effort="0.0"/>
            <!-- <calibration rising_and_or_falling=""/> -->
        </joint>

        <link name="${leg_name}-Thigh_link"/>

        <joint name="${leg_name}-Thight-part1_joint" type="fixed">
            <parent link="${leg_name}-Thigh_link"/>
            <child link="${leg_name}-Thigh-part1_link"/>
            <origin xyz="${0.0077 + 0.0043} 0 0" rpy="${-pi/2} ${0} ${-pi/2}"/>
        </joint>

        <link name="${leg_name}-Thigh-part1_link">
            <visual>
                <origin xyz="0 0 0" rpy="0 0 0"/>
                <geometry>
                    <mesh filename="package://quadruped_robot_description/meshes/thigh.stl"/>
                </geometry>
            </visual>
            <!--<collision>
                <origin xyz="0 -0.0275 0" rpy="0 0 0" />
                <geometry>
                    <box size="0.02 0.075 0.0045"/>
                </geometry>
            </collision>-->
            <collision>
                <origin xyz="0 0 0" rpy="0 0 0" />
                <geometry>
                    <mesh filename="package://quadruped_robot_description/meshes/thigh_collision.stl"/>
                </geometry>
            </collision>
            <xacro:thigh_inertial/>
        </link>

        <gazebo reference="${leg_name}-Thigh_link">
            <selfCollide>true</selfCollide>
        </gazebo>

        <!--###### knee flexion/extension joint ######-->
        <joint name="${leg_name}-KFE_joint" type="revolute">
            <parent link="${leg_name}-Thigh_link"/>
            <child link="${leg_name}-Shank_link"/>
            <origin xyz="0 0 0.055" rpy="${-pi/2 * reflect_fh * reflect_lr} 0 0"/>
            <axis xyz="1 0 0"/>
            <dynamics damping="0.00001"/>
            <limit lower="0.0" upper="${pi}" velocity="1.0" effort="0.0"/>
            <!-- <calibration rising_and_or_falling=""/> -->
        </joint>

        <link name="${leg_name}-Shank_link"/>

        <joint name="${leg_name}-Shank_joint" type="fixed">
            <parent link="${leg_name}-Shank_link"/>
            <child link="${leg_name}-Shank-part1_link"/>
            <origin xyz="0 0 0" rpy="0 ${pi/2 * reflect_fh * reflect_lr} ${pi}"/>
        </joint>

        <link name="${leg_name}-Shank-part1_link">
            <visual>
                <origin xyz="0 0 0" rpy="0 0 0"/>
                <geometry>
                    <mesh filename="package://quadruped_robot_description/meshes/shank.stl"/>
                </geometry>
            </visual>
            <!--<collision>
                <origin xyz="0 -0.04 0" rpy="0 0 0" />
                <geometry>
                    <box size="0.01 0.04 0.0045"/>
                </geometry>
            </collision>-->
            <collision>
                <origin xyz="0 0 0" rpy="0 0 0" />
                <geometry>
                    <mesh filename="package://quadruped_robot_description/meshes/shank_collision.stl"/>
                </geometry>
            </collision>

            <xacro:shank_inertial/>
        </link>

        <xacro:servo name_suffix="${leg_name}-KFE" parent="${leg_name}-Shank_link"
            xyz="${0.0077 + 0.0043/2} 0 0"
            rpy="0 0 ${-pi/2}"/>

        <gazebo reference="${leg_name}-Shank_link">
            <selfCollide>true</selfCollide>
        </gazebo>

    </xacro:macro>

    <xacro:macro name="servo" params="name_suffix parent xyz rpy">
        <xacro:property name="servo_name_prefix" value="servo-${name_suffix}"/>
        <joint name="${servo_name_prefix}_joint" type="fixed">
            <parent link="${parent}"/>
            <child link="${servo_name_prefix}_link"/>
            <origin xyz="${xyz}" rpy="${rpy}"/>
        </joint>
        <link name="${servo_name_prefix}_link">
            <visual>
                <origin xyz="0 0 0" rpy="0 0 0"/>
                <geometry>
                    <mesh filename="package://quadruped_robot_description/meshes/emax_es08a.stl"/>
                </geometry>
            </visual>
            <collision>
                <origin xyz="${-0.024/2 + 0.0058} ${-(0.0077 + 0.0043 + 0.017/2)} 0" rpy="0 0 0"/>
                <geometry>
                    <box size="0.024 0.017 0.012"/>
                </geometry>
            </collision>
            <xacro:servo_inertial/>
        </link>
        <gazebo reference="${servo_name_prefix}_link">
            <selfCollide>true</selfCollide>
        </gazebo>
    </xacro:macro>

    <joint name="body_bottom-plate_joint" type="fixed">"
        <parent link="body_link"/>
        <child link="body_bottom-plate_link"/>
        <origin xyz="0 0 ${-(0.030 + 0.00215)}" rpy="${pi} 0 ${pi/2}"/>
    </joint>

    <link name="body_bottom-plate_link">
        <visual>
            <origin xyz="0 0 0" rpy="0 0 0"/>
            <geometry>
                <mesh filename="package://quadruped_robot_description/meshes/body_bottom-plate.stl"/>
            </geometry>
        </visual>
        <collision>
            <origin xyz="0 0 0.0022" rpy="0 0 0" />
            <geometry>
                <box size="0.076 0.076 0.0044"/>
            </geometry>
        </collision>
        <xacro:body_bottom-plate_inertial/>
    </link>

    <xacro:macro name="battery" params="nr reflect_lr">
        <joint name="body_battery${nr}_joint" type="fixed">"
            <parent link="body_link"/>
            <child link="body_battery${nr}_link"/>
            <origin xyz="0 ${reflect_lr * 0.01} ${-(0.009 + 0.0024)}" rpy="0 ${pi/2} 0"/>
        </joint>

        <link name="body_battery${nr}_link">
            <visual>
                <origin xyz="0 0 0" rpy="0 0 0"/>
                <geometry>
                    <cylinder radius="0.009" length="0.065"/>
                </geometry>
            </visual>
            <!--<collision>
                <origin xyz="0 0 0" rpy="0 0 0" />
                <geometry>
                    <cylinder radius="0.009" length="0.065"/>
                </geometry>
            </collision>-->
            <xacro:body_battery_inertial/>
        </link>
    </xacro:macro>

    <joint name="body_electronic_joint" type="fixed">
        <parent link="body_link"/>
        <child link="body_electronic_link"/>
        <origin xyz="0 0 ${0.0043 + 0.0081}" rpy="0 0 0"/>
    </joint>

    <link name="body_electronic_link">
        <visual>
            <origin xyz="0 0 0.001" rpy="0 0 0"/>
            <geometry>
                <box size="0.061 0.054 0.002"/>
            </geometry>
        </visual>
        <xacro:body_electronic_inertial/>
    </link>

    <gazebo reference="body_link">
        <selfCollide>true</selfCollide>
    </gazebo>

</robot>
